
===================================BUG REPORT===================================
Welcome to bitsandbytes. For bug reports, please run

python -m bitsandbytes

 and submit this information together with your error trace to: https://github.com/TimDettmers/bitsandbytes/issues
================================================================================

===================================BUG REPORT===================================
Welcome to bitsandbytes. For bug reports, please run

python -m bitsandbytes

 and submit this information together with your error trace to: https://github.com/TimDettmers/bitsandbytes/issues
================================================================================
bin /opt/conda/lib/python3.10/site-packages/bitsandbytes/libbitsandbytes_cuda117_nocublaslt.so
bin /opt/conda/lib/python3.10/site-packages/bitsandbytes/libbitsandbytes_cuda117_nocublaslt.so
/opt/conda/lib/python3.10/site-packages/bitsandbytes/cuda_setup/main.py:149: UserWarning: WARNING: The following directories listed in your path were found to be non-existent: {PosixPath('/usr/local/nvidia/lib64'), PosixPath('/usr/local/nvidia/lib')}
  warn(msg)
/opt/conda/lib/python3.10/site-packages/bitsandbytes/cuda_setup/main.py:149: UserWarning: /usr/local/nvidia/lib:/usr/local/nvidia/lib64 did not contain ['libcudart.so', 'libcudart.so.11.0', 'libcudart.so.12.0'] as expected! Searching further paths...
  warn(msg)
/opt/conda/lib/python3.10/site-packages/bitsandbytes/cuda_setup/main.py:149: UserWarning: WARNING: The following directories listed in your path were found to be non-existent: {PosixPath('/tmp/torchelastic_z11zvzbn/none_zp50jaxo/attempt_0/1/error.json')}
  warn(msg)
CUDA_SETUP: WARNING! libcudart.so not found in any environmental path. Searching in backup paths...
/opt/conda/lib/python3.10/site-packages/bitsandbytes/cuda_setup/main.py:149: UserWarning: Found duplicate ['libcudart.so', 'libcudart.so.11.0', 'libcudart.so.12.0'] files: {PosixPath('/usr/local/cuda/lib64/libcudart.so'), PosixPath('/usr/local/cuda/lib64/libcudart.so.11.0')}.. We'll flip a coin and try one of these, in order to fail forward.
Either way, this might cause trouble in the future:
If you get `CUDA error: invalid device function` errors, the above might be the cause and the solution is to make sure only one ['libcudart.so', 'libcudart.so.11.0', 'libcudart.so.12.0'] in the paths that we search based on your env.
  warn(msg)
CUDA SETUP: CUDA runtime path found: /usr/local/cuda/lib64/libcudart.so
CUDA SETUP: Highest compute capability among GPUs detected: 6.0
CUDA SETUP: Detected CUDA version 117
/opt/conda/lib/python3.10/site-packages/bitsandbytes/cuda_setup/main.py:149: UserWarning: WARNING: Compute capability < 7.5 detected! Only slow 8-bit matmul is supported for your GPU!
  warn(msg)
CUDA SETUP: Loading binary /opt/conda/lib/python3.10/site-packages/bitsandbytes/libbitsandbytes_cuda117_nocublaslt.so...
/opt/conda/lib/python3.10/site-packages/bitsandbytes/cuda_setup/main.py:149: UserWarning: WARNING: The following directories listed in your path were found to be non-existent: {PosixPath('/usr/local/nvidia/lib'), PosixPath('/usr/local/nvidia/lib64')}
  warn(msg)
/opt/conda/lib/python3.10/site-packages/bitsandbytes/cuda_setup/main.py:149: UserWarning: /usr/local/nvidia/lib:/usr/local/nvidia/lib64 did not contain ['libcudart.so', 'libcudart.so.11.0', 'libcudart.so.12.0'] as expected! Searching further paths...
  warn(msg)
/opt/conda/lib/python3.10/site-packages/bitsandbytes/cuda_setup/main.py:149: UserWarning: WARNING: The following directories listed in your path were found to be non-existent: {PosixPath('/tmp/torchelastic_z11zvzbn/none_zp50jaxo/attempt_0/0/error.json')}
  warn(msg)
CUDA_SETUP: WARNING! libcudart.so not found in any environmental path. Searching in backup paths...
/opt/conda/lib/python3.10/site-packages/bitsandbytes/cuda_setup/main.py:149: UserWarning: Found duplicate ['libcudart.so', 'libcudart.so.11.0', 'libcudart.so.12.0'] files: {PosixPath('/usr/local/cuda/lib64/libcudart.so.11.0'), PosixPath('/usr/local/cuda/lib64/libcudart.so')}.. We'll flip a coin and try one of these, in order to fail forward.
Either way, this might cause trouble in the future:
If you get `CUDA error: invalid device function` errors, the above might be the cause and the solution is to make sure only one ['libcudart.so', 'libcudart.so.11.0', 'libcudart.so.12.0'] in the paths that we search based on your env.
  warn(msg)
CUDA SETUP: CUDA runtime path found: /usr/local/cuda/lib64/libcudart.so.11.0
CUDA SETUP: Highest compute capability among GPUs detected: 6.0
CUDA SETUP: Detected CUDA version 117
/opt/conda/lib/python3.10/site-packages/bitsandbytes/cuda_setup/main.py:149: UserWarning: WARNING: Compute capability < 7.5 detected! Only slow 8-bit matmul is supported for your GPU!
  warn(msg)
CUDA SETUP: Loading binary /opt/conda/lib/python3.10/site-packages/bitsandbytes/libbitsandbytes_cuda117_nocublaslt.so...
rank 2 is in stage 2
rank 1 is in stage 1
create layer: 32|create layer: 24|create layer: 33|create layer: 25|create layer: 34|create layer: 26|create layer: 35|create layer: 27|create layer: 28|create layer: 36|create layer: 29|create layer: 37|create layer: 30|create layer: 38|create layer: 31|create layer: 39|Stage 1 module sharded
Stage 1 kv initialized
Stage 2 module sharded
Stage 2 kv initialized
rank_src: 1, rank_dst: 3, rank: 2, results_cb: Nonerank_src: 0, rank_dst: 2, rank: 1, results_cb: None

2023-05-27 06:02:31,189 - INFO - handle_cmd: stop
2023-05-27 06:02:31,209 - INFO - handle_cmd: stop
ERROR:torch.distributed.elastic.agent.server.api:Error waiting on exit barrier. Elapsed: 25.862425565719604 seconds
Traceback (most recent call last):
  File "/opt/conda/lib/python3.10/site-packages/torch/distributed/elastic/agent/server/api.py", line 920, in _exit_barrier
    store_util.barrier(
  File "/opt/conda/lib/python3.10/site-packages/torch/distributed/elastic/utils/store.py", line 78, in barrier
    synchronize(store, data, rank, world_size, key_prefix, barrier_timeout)
  File "/opt/conda/lib/python3.10/site-packages/torch/distributed/elastic/utils/store.py", line 64, in synchronize
    agent_data = get_all(store, rank, key_prefix, world_size)
  File "/opt/conda/lib/python3.10/site-packages/torch/distributed/elastic/utils/store.py", line 34, in get_all
    data = store.get(f"{prefix}{idx}")
RuntimeError: Connection reset by peer
