
===================================BUG REPORT===================================
Welcome to bitsandbytes. For bug reports, please run

python -m bitsandbytes

 and submit this information together with your error trace to: https://github.com/TimDettmers/bitsandbytes/issues
================================================================================

===================================BUG REPORT===================================
Welcome to bitsandbytes. For bug reports, please run

python -m bitsandbytes

 and submit this information together with your error trace to: https://github.com/TimDettmers/bitsandbytes/issues
================================================================================

===================================BUG REPORT===================================
Welcome to bitsandbytes. For bug reports, please run

python -m bitsandbytes

 and submit this information together with your error trace to: https://github.com/TimDettmers/bitsandbytes/issues
================================================================================

===================================BUG REPORT===================================
Welcome to bitsandbytes. For bug reports, please run

python -m bitsandbytes

 and submit this information together with your error trace to: https://github.com/TimDettmers/bitsandbytes/issues
================================================================================
bin /opt/conda/lib/python3.10/site-packages/bitsandbytes/libbitsandbytes_cuda117.so
/opt/conda/lib/python3.10/site-packages/bitsandbytes/cuda_setup/main.py:145: UserWarning: WARNING: The following directories listed in your path were found to be non-existent: {PosixPath('/usr/local/nvidia/lib64'), PosixPath('/usr/local/nvidia/lib')}
  warn(msg)
/opt/conda/lib/python3.10/site-packages/bitsandbytes/cuda_setup/main.py:145: UserWarning: /usr/local/nvidia/lib:/usr/local/nvidia/lib64 did not contain ['libcudart.so', 'libcudart.so.11.0', 'libcudart.so.12.0'] as expected! Searching further paths...
  warn(msg)
/opt/conda/lib/python3.10/site-packages/bitsandbytes/cuda_setup/main.py:145: UserWarning: WARNING: The following directories listed in your path were found to be non-existent: {PosixPath('/tmp/torchelastic_es2qbcmc/none_etwkv1n9/attempt_0/1/error.json')}
  warn(msg)
CUDA_SETUP: WARNING! libcudart.so not found in any environmental path. Searching in backup paths...
/opt/conda/lib/python3.10/site-packages/bitsandbytes/cuda_setup/main.py:145: UserWarning: Found duplicate ['libcudart.so', 'libcudart.so.11.0', 'libcudart.so.12.0'] files: {PosixPath('/usr/local/cuda/lib64/libcudart.so.11.0'), PosixPath('/usr/local/cuda/lib64/libcudart.so')}.. We'll flip a coin and try one of these, in order to fail forward.
Either way, this might cause trouble in the future:
If you get `CUDA error: invalid device function` errors, the above might be the cause and the solution is to make sure only one ['libcudart.so', 'libcudart.so.11.0', 'libcudart.so.12.0'] in the paths that we search based on your env.
  warn(msg)
CUDA SETUP: CUDA runtime path found: /usr/local/cuda/lib64/libcudart.so.11.0
CUDA SETUP: Highest compute capability among GPUs detected: 8.0
CUDA SETUP: Detected CUDA version 117
CUDA SETUP: Loading binary /opt/conda/lib/python3.10/site-packages/bitsandbytes/libbitsandbytes_cuda117.so...
bin /opt/conda/lib/python3.10/site-packages/bitsandbytes/libbitsandbytes_cuda117.so
/opt/conda/lib/python3.10/site-packages/bitsandbytes/cuda_setup/main.py:145: UserWarning: WARNING: The following directories listed in your path were found to be non-existent: {PosixPath('/usr/local/nvidia/lib'), PosixPath('/usr/local/nvidia/lib64')}
  warn(msg)
/opt/conda/lib/python3.10/site-packages/bitsandbytes/cuda_setup/main.py:145: UserWarning: /usr/local/nvidia/lib:/usr/local/nvidia/lib64 did not contain ['libcudart.so', 'libcudart.so.11.0', 'libcudart.so.12.0'] as expected! Searching further paths...
  warn(msg)
/opt/conda/lib/python3.10/site-packages/bitsandbytes/cuda_setup/main.py:145: UserWarning: WARNING: The following directories listed in your path were found to be non-existent: {PosixPath('/tmp/torchelastic_es2qbcmc/none_etwkv1n9/attempt_0/0/error.json')}
  warn(msg)
CUDA_SETUP: WARNING! libcudart.so not found in any environmental path. Searching in backup paths...
/opt/conda/lib/python3.10/site-packages/bitsandbytes/cuda_setup/main.py:145: UserWarning: Found duplicate ['libcudart.so', 'libcudart.so.11.0', 'libcudart.so.12.0'] files: {PosixPath('/usr/local/cuda/lib64/libcudart.so.11.0'), PosixPath('/usr/local/cuda/lib64/libcudart.so')}.. We'll flip a coin and try one of these, in order to fail forward.
Either way, this might cause trouble in the future:
If you get `CUDA error: invalid device function` errors, the above might be the cause and the solution is to make sure only one ['libcudart.so', 'libcudart.so.11.0', 'libcudart.so.12.0'] in the paths that we search based on your env.
  warn(msg)
CUDA SETUP: CUDA runtime path found: /usr/local/cuda/lib64/libcudart.so.11.0
CUDA SETUP: Highest compute capability among GPUs detected: 8.0
CUDA SETUP: Detected CUDA version 117
CUDA SETUP: Loading binary /opt/conda/lib/python3.10/site-packages/bitsandbytes/libbitsandbytes_cuda117.so...
bin /opt/conda/lib/python3.10/site-packages/bitsandbytes/libbitsandbytes_cuda117.so
/opt/conda/lib/python3.10/site-packages/bitsandbytes/cuda_setup/main.py:145: UserWarning: WARNING: The following directories listed in your path were found to be non-existent: {PosixPath('/usr/local/nvidia/lib'), PosixPath('/usr/local/nvidia/lib64')}
  warn(msg)
/opt/conda/lib/python3.10/site-packages/bitsandbytes/cuda_setup/main.py:145: UserWarning: /usr/local/nvidia/lib:/usr/local/nvidia/lib64 did not contain ['libcudart.so', 'libcudart.so.11.0', 'libcudart.so.12.0'] as expected! Searching further paths...
  warn(msg)
/opt/conda/lib/python3.10/site-packages/bitsandbytes/cuda_setup/main.py:145: UserWarning: WARNING: The following directories listed in your path were found to be non-existent: {PosixPath('/tmp/torchelastic_es2qbcmc/none_etwkv1n9/attempt_0/3/error.json')}
  warn(msg)
CUDA_SETUP: WARNING! libcudart.so not found in any environmental path. Searching in backup paths...
/opt/conda/lib/python3.10/site-packages/bitsandbytes/cuda_setup/main.py:145: UserWarning: Found duplicate ['libcudart.so', 'libcudart.so.11.0', 'libcudart.so.12.0'] files: {PosixPath('/usr/local/cuda/lib64/libcudart.so.11.0'), PosixPath('/usr/local/cuda/lib64/libcudart.so')}.. We'll flip a coin and try one of these, in order to fail forward.
Either way, this might cause trouble in the future:
If you get `CUDA error: invalid device function` errors, the above might be the cause and the solution is to make sure only one ['libcudart.so', 'libcudart.so.11.0', 'libcudart.so.12.0'] in the paths that we search based on your env.
  warn(msg)
CUDA SETUP: CUDA runtime path found: /usr/local/cuda/lib64/libcudart.so.11.0
CUDA SETUP: Highest compute capability among GPUs detected: 8.0
CUDA SETUP: Detected CUDA version 117
CUDA SETUP: Loading binary /opt/conda/lib/python3.10/site-packages/bitsandbytes/libbitsandbytes_cuda117.so...
bin /opt/conda/lib/python3.10/site-packages/bitsandbytes/libbitsandbytes_cuda117.so
/opt/conda/lib/python3.10/site-packages/bitsandbytes/cuda_setup/main.py:145: UserWarning: WARNING: The following directories listed in your path were found to be non-existent: {PosixPath('/usr/local/nvidia/lib64'), PosixPath('/usr/local/nvidia/lib')}
  warn(msg)
/opt/conda/lib/python3.10/site-packages/bitsandbytes/cuda_setup/main.py:145: UserWarning: /usr/local/nvidia/lib:/usr/local/nvidia/lib64 did not contain ['libcudart.so', 'libcudart.so.11.0', 'libcudart.so.12.0'] as expected! Searching further paths...
  warn(msg)
/opt/conda/lib/python3.10/site-packages/bitsandbytes/cuda_setup/main.py:145: UserWarning: WARNING: The following directories listed in your path were found to be non-existent: {PosixPath('/tmp/torchelastic_es2qbcmc/none_etwkv1n9/attempt_0/2/error.json')}
  warn(msg)
CUDA_SETUP: WARNING! libcudart.so not found in any environmental path. Searching in backup paths...
/opt/conda/lib/python3.10/site-packages/bitsandbytes/cuda_setup/main.py:145: UserWarning: Found duplicate ['libcudart.so', 'libcudart.so.11.0', 'libcudart.so.12.0'] files: {PosixPath('/usr/local/cuda/lib64/libcudart.so.11.0'), PosixPath('/usr/local/cuda/lib64/libcudart.so')}.. We'll flip a coin and try one of these, in order to fail forward.
Either way, this might cause trouble in the future:
If you get `CUDA error: invalid device function` errors, the above might be the cause and the solution is to make sure only one ['libcudart.so', 'libcudart.so.11.0', 'libcudart.so.12.0'] in the paths that we search based on your env.
  warn(msg)
CUDA SETUP: CUDA runtime path found: /usr/local/cuda/lib64/libcudart.so.11.0
CUDA SETUP: Highest compute capability among GPUs detected: 8.0
CUDA SETUP: Detected CUDA version 117
CUDA SETUP: Loading binary /opt/conda/lib/python3.10/site-packages/bitsandbytes/libbitsandbytes_cuda117.so...
rank 4 is in stage 4
rank 5 is in stage 5
rank 6 is in stage 6
rank 7 is in stage 7
create layer: 30|create layer: 40|create layer: 50|create layer: 60|create layer: 31|create layer: 51|create layer: 61|create layer: 41|create layer: 52|create layer: 32|create layer: 62|create layer: 42|create layer: 53|create layer: 33|create layer: 63|create layer: 43|create layer: 54|create layer: 34|create layer: 64|create layer: 44|create layer: 55|create layer: 35|create layer: 65|create layer: 45|create layer: 56|create layer: 36|create layer: 66|create layer: 46|create layer: 57|create layer: 37|create layer: 67|create layer: 47|create layer: 58|create layer: 38|create layer: 68|create layer: 48|create layer: 59|create layer: 39|create layer: 69|Stage 6 module sharded
Stage 6 kv initialized
Stage 4 module sharded
Stage 4 kv initialized
Stage 7 module sharded
Stage 7 kv initialized
create layer: 49|Stage 5 module sharded
Stage 5 kv initialized
rank_src: 6, rank_dst: 0, rank: 7, results_cb: None
rank_src: 5, rank_dst: 7, rank: 6, results_cb: None
rank_src: 4, rank_dst: 6, rank: 5, results_cb: None
rank_src: 3, rank_dst: 5, rank: 4, results_cb: None
/opt/conda/lib/python3.10/site-packages/qpipe/p2p/util.py:32: UserWarning: TypedStorage is deprecated. It will be removed in the future and UntypedStorage will be the only storage class. This should only matter to you if you are using storages directly.  To access UntypedStorage directly, use tensor.untyped_storage() instead of tensor.storage()
  byte_storage = torch.ByteStorage.from_buffer(bytes_io.getvalue())  # type: ignore[attr-defined]
/opt/conda/lib/python3.10/site-packages/qpipe/p2p/util.py:32: UserWarning: TypedStorage is deprecated. It will be removed in the future and UntypedStorage will be the only storage class. This should only matter to you if you are using storages directly.  To access UntypedStorage directly, use tensor.untyped_storage() instead of tensor.storage()
  byte_storage = torch.ByteStorage.from_buffer(bytes_io.getvalue())  # type: ignore[attr-defined]
/opt/conda/lib/python3.10/site-packages/qpipe/p2p/util.py:32: UserWarning: TypedStorage is deprecated. It will be removed in the future and UntypedStorage will be the only storage class. This should only matter to you if you are using storages directly.  To access UntypedStorage directly, use tensor.untyped_storage() instead of tensor.storage()
  byte_storage = torch.ByteStorage.from_buffer(bytes_io.getvalue())  # type: ignore[attr-defined]
/opt/conda/lib/python3.10/site-packages/qpipe/p2p/util.py:32: UserWarning: TypedStorage is deprecated. It will be removed in the future and UntypedStorage will be the only storage class. This should only matter to you if you are using storages directly.  To access UntypedStorage directly, use tensor.untyped_storage() instead of tensor.storage()
  byte_storage = torch.ByteStorage.from_buffer(bytes_io.getvalue())  # type: ignore[attr-defined]
2023-05-27 13:45:16,714 - INFO - handle_cmd: stop
2023-05-27 13:45:16,721 - INFO - handle_cmd: stop
2023-05-27 13:45:16,731 - INFO - handle_cmd: stop
2023-05-27 13:45:16,763 - INFO - handle_cmd: stop
Traceback (most recent call last):
  File "/workspace/qpipe/tests/main_p2p.py", line 329, in <module>
    simple_queue_thread.join()
AttributeError: 'NoneType' object has no attribute 'join'
Traceback (most recent call last):
  File "/workspace/qpipe/tests/main_p2p.py", line 329, in <module>
    simple_queue_thread.join()
AttributeError: 'NoneType' object has no attribute 'join'
Traceback (most recent call last):
  File "/workspace/qpipe/tests/main_p2p.py", line 329, in <module>
    simple_queue_thread.join()
AttributeError: 'NoneType' object has no attribute 'join'
Traceback (most recent call last):
  File "/workspace/qpipe/tests/main_p2p.py", line 329, in <module>
    simple_queue_thread.join()
AttributeError: 'NoneType' object has no attribute 'join'
ERROR:torch.distributed.elastic.multiprocessing.api:failed (exitcode: 1) local_rank: 0 (pid: 188921) of binary: /opt/conda/bin/python
Traceback (most recent call last):
  File "/opt/conda/bin/torchrun", line 33, in <module>
    sys.exit(load_entry_point('torch==2.0.0', 'console_scripts', 'torchrun')())
  File "/opt/conda/lib/python3.10/site-packages/torch/distributed/elastic/multiprocessing/errors/__init__.py", line 346, in wrapper
    return f(*args, **kwargs)
  File "/opt/conda/lib/python3.10/site-packages/torch/distributed/run.py", line 794, in main
    run(args)
  File "/opt/conda/lib/python3.10/site-packages/torch/distributed/run.py", line 785, in run
    elastic_launch(
  File "/opt/conda/lib/python3.10/site-packages/torch/distributed/launcher/api.py", line 134, in __call__
    return launch_agent(self._config, self._entrypoint, list(args))
  File "/opt/conda/lib/python3.10/site-packages/torch/distributed/launcher/api.py", line 250, in launch_agent
    raise ChildFailedError(
torch.distributed.elastic.multiprocessing.errors.ChildFailedError: 
============================================================
main_p2p.py FAILED
------------------------------------------------------------
Failures:
[1]:
  time      : 2023-05-27_13:45:19
  host      : net-g14
  rank      : 5 (local_rank: 1)
  exitcode  : 1 (pid: 188922)
  error_file: <N/A>
  traceback : To enable traceback see: https://pytorch.org/docs/stable/elastic/errors.html
[2]:
  time      : 2023-05-27_13:45:19
  host      : net-g14
  rank      : 6 (local_rank: 2)
  exitcode  : 1 (pid: 188923)
  error_file: <N/A>
  traceback : To enable traceback see: https://pytorch.org/docs/stable/elastic/errors.html
[3]:
  time      : 2023-05-27_13:45:19
  host      : net-g14
  rank      : 7 (local_rank: 3)
  exitcode  : 1 (pid: 188924)
  error_file: <N/A>
  traceback : To enable traceback see: https://pytorch.org/docs/stable/elastic/errors.html
------------------------------------------------------------
Root Cause (first observed failure):
[0]:
  time      : 2023-05-27_13:45:19
  host      : net-g14
  rank      : 4 (local_rank: 0)
  exitcode  : 1 (pid: 188921)
  error_file: <N/A>
  traceback : To enable traceback see: https://pytorch.org/docs/stable/elastic/errors.html
============================================================
