
===================================BUG REPORT===================================
Welcome to bitsandbytes. For bug reports, please run

python -m bitsandbytes

 and submit this information together with your error trace to: https://github.com/TimDettmers/bitsandbytes/issues
================================================================================

===================================BUG REPORT===================================
Welcome to bitsandbytes. For bug reports, please run

python -m bitsandbytes

 and submit this information together with your error trace to: https://github.com/TimDettmers/bitsandbytes/issues
================================================================================

===================================BUG REPORT===================================
Welcome to bitsandbytes. For bug reports, please run

python -m bitsandbytes

 and submit this information together with your error trace to: https://github.com/TimDettmers/bitsandbytes/issues
================================================================================

===================================BUG REPORT===================================
Welcome to bitsandbytes. For bug reports, please run

python -m bitsandbytes

 and submit this information together with your error trace to: https://github.com/TimDettmers/bitsandbytes/issues
================================================================================
bin /opt/conda/lib/python3.10/site-packages/bitsandbytes/libbitsandbytes_cuda117.so
/opt/conda/lib/python3.10/site-packages/bitsandbytes/cuda_setup/main.py:145: UserWarning: WARNING: The following directories listed in your path were found to be non-existent: {PosixPath('/usr/local/nvidia/lib64'), PosixPath('/usr/local/nvidia/lib')}
  warn(msg)
/opt/conda/lib/python3.10/site-packages/bitsandbytes/cuda_setup/main.py:145: UserWarning: /usr/local/nvidia/lib:/usr/local/nvidia/lib64 did not contain ['libcudart.so', 'libcudart.so.11.0', 'libcudart.so.12.0'] as expected! Searching further paths...
  warn(msg)
/opt/conda/lib/python3.10/site-packages/bitsandbytes/cuda_setup/main.py:145: UserWarning: WARNING: The following directories listed in your path were found to be non-existent: {PosixPath('/tmp/torchelastic_yzshaw9j/none_4k2ik13l/attempt_0/1/error.json')}
  warn(msg)
CUDA_SETUP: WARNING! libcudart.so not found in any environmental path. Searching in backup paths...
/opt/conda/lib/python3.10/site-packages/bitsandbytes/cuda_setup/main.py:145: UserWarning: Found duplicate ['libcudart.so', 'libcudart.so.11.0', 'libcudart.so.12.0'] files: {PosixPath('/usr/local/cuda/lib64/libcudart.so.11.0'), PosixPath('/usr/local/cuda/lib64/libcudart.so')}.. We'll flip a coin and try one of these, in order to fail forward.
Either way, this might cause trouble in the future:
If you get `CUDA error: invalid device function` errors, the above might be the cause and the solution is to make sure only one ['libcudart.so', 'libcudart.so.11.0', 'libcudart.so.12.0'] in the paths that we search based on your env.
  warn(msg)
CUDA SETUP: CUDA runtime path found: /usr/local/cuda/lib64/libcudart.so.11.0
CUDA SETUP: Highest compute capability among GPUs detected: 8.0
CUDA SETUP: Detected CUDA version 117
CUDA SETUP: Loading binary /opt/conda/lib/python3.10/site-packages/bitsandbytes/libbitsandbytes_cuda117.so...
bin /opt/conda/lib/python3.10/site-packages/bitsandbytes/libbitsandbytes_cuda117.so
/opt/conda/lib/python3.10/site-packages/bitsandbytes/cuda_setup/main.py:145: UserWarning: WARNING: The following directories listed in your path were found to be non-existent: {PosixPath('/usr/local/nvidia/lib'), PosixPath('/usr/local/nvidia/lib64')}
  warn(msg)
/opt/conda/lib/python3.10/site-packages/bitsandbytes/cuda_setup/main.py:145: UserWarning: /usr/local/nvidia/lib:/usr/local/nvidia/lib64 did not contain ['libcudart.so', 'libcudart.so.11.0', 'libcudart.so.12.0'] as expected! Searching further paths...
  warn(msg)
/opt/conda/lib/python3.10/site-packages/bitsandbytes/cuda_setup/main.py:145: UserWarning: WARNING: The following directories listed in your path were found to be non-existent: {PosixPath('/tmp/torchelastic_yzshaw9j/none_4k2ik13l/attempt_0/0/error.json')}
  warn(msg)
CUDA_SETUP: WARNING! libcudart.so not found in any environmental path. Searching in backup paths...
/opt/conda/lib/python3.10/site-packages/bitsandbytes/cuda_setup/main.py:145: UserWarning: Found duplicate ['libcudart.so', 'libcudart.so.11.0', 'libcudart.so.12.0'] files: {PosixPath('/usr/local/cuda/lib64/libcudart.so.11.0'), PosixPath('/usr/local/cuda/lib64/libcudart.so')}.. We'll flip a coin and try one of these, in order to fail forward.
Either way, this might cause trouble in the future:
If you get `CUDA error: invalid device function` errors, the above might be the cause and the solution is to make sure only one ['libcudart.so', 'libcudart.so.11.0', 'libcudart.so.12.0'] in the paths that we search based on your env.
  warn(msg)
CUDA SETUP: CUDA runtime path found: /usr/local/cuda/lib64/libcudart.so.11.0
CUDA SETUP: Highest compute capability among GPUs detected: 8.0
CUDA SETUP: Detected CUDA version 117
CUDA SETUP: Loading binary /opt/conda/lib/python3.10/site-packages/bitsandbytes/libbitsandbytes_cuda117.so...
bin /opt/conda/lib/python3.10/site-packages/bitsandbytes/libbitsandbytes_cuda117.so
/opt/conda/lib/python3.10/site-packages/bitsandbytes/cuda_setup/main.py:145: UserWarning: WARNING: The following directories listed in your path were found to be non-existent: {PosixPath('/usr/local/nvidia/lib64'), PosixPath('/usr/local/nvidia/lib')}
  warn(msg)
/opt/conda/lib/python3.10/site-packages/bitsandbytes/cuda_setup/main.py:145: UserWarning: /usr/local/nvidia/lib:/usr/local/nvidia/lib64 did not contain ['libcudart.so', 'libcudart.so.11.0', 'libcudart.so.12.0'] as expected! Searching further paths...
  warn(msg)
/opt/conda/lib/python3.10/site-packages/bitsandbytes/cuda_setup/main.py:145: UserWarning: WARNING: The following directories listed in your path were found to be non-existent: {PosixPath('/tmp/torchelastic_yzshaw9j/none_4k2ik13l/attempt_0/2/error.json')}
  warn(msg)
CUDA_SETUP: WARNING! libcudart.so not found in any environmental path. Searching in backup paths...
/opt/conda/lib/python3.10/site-packages/bitsandbytes/cuda_setup/main.py:145: UserWarning: Found duplicate ['libcudart.so', 'libcudart.so.11.0', 'libcudart.so.12.0'] files: {PosixPath('/usr/local/cuda/lib64/libcudart.so'), PosixPath('/usr/local/cuda/lib64/libcudart.so.11.0')}.. We'll flip a coin and try one of these, in order to fail forward.
Either way, this might cause trouble in the future:
If you get `CUDA error: invalid device function` errors, the above might be the cause and the solution is to make sure only one ['libcudart.so', 'libcudart.so.11.0', 'libcudart.so.12.0'] in the paths that we search based on your env.
  warn(msg)
CUDA SETUP: CUDA runtime path found: /usr/local/cuda/lib64/libcudart.so
CUDA SETUP: Highest compute capability among GPUs detected: 8.0
CUDA SETUP: Detected CUDA version 117
CUDA SETUP: Loading binary /opt/conda/lib/python3.10/site-packages/bitsandbytes/libbitsandbytes_cuda117.so...
bin /opt/conda/lib/python3.10/site-packages/bitsandbytes/libbitsandbytes_cuda117.so
/opt/conda/lib/python3.10/site-packages/bitsandbytes/cuda_setup/main.py:145: UserWarning: WARNING: The following directories listed in your path were found to be non-existent: {PosixPath('/usr/local/nvidia/lib'), PosixPath('/usr/local/nvidia/lib64')}
  warn(msg)
/opt/conda/lib/python3.10/site-packages/bitsandbytes/cuda_setup/main.py:145: UserWarning: /usr/local/nvidia/lib:/usr/local/nvidia/lib64 did not contain ['libcudart.so', 'libcudart.so.11.0', 'libcudart.so.12.0'] as expected! Searching further paths...
  warn(msg)
/opt/conda/lib/python3.10/site-packages/bitsandbytes/cuda_setup/main.py:145: UserWarning: WARNING: The following directories listed in your path were found to be non-existent: {PosixPath('/tmp/torchelastic_yzshaw9j/none_4k2ik13l/attempt_0/3/error.json')}
  warn(msg)
CUDA_SETUP: WARNING! libcudart.so not found in any environmental path. Searching in backup paths...
/opt/conda/lib/python3.10/site-packages/bitsandbytes/cuda_setup/main.py:145: UserWarning: Found duplicate ['libcudart.so', 'libcudart.so.11.0', 'libcudart.so.12.0'] files: {PosixPath('/usr/local/cuda/lib64/libcudart.so.11.0'), PosixPath('/usr/local/cuda/lib64/libcudart.so')}.. We'll flip a coin and try one of these, in order to fail forward.
Either way, this might cause trouble in the future:
If you get `CUDA error: invalid device function` errors, the above might be the cause and the solution is to make sure only one ['libcudart.so', 'libcudart.so.11.0', 'libcudart.so.12.0'] in the paths that we search based on your env.
  warn(msg)
CUDA SETUP: CUDA runtime path found: /usr/local/cuda/lib64/libcudart.so.11.0
CUDA SETUP: Highest compute capability among GPUs detected: 8.0
CUDA SETUP: Detected CUDA version 117
CUDA SETUP: Loading binary /opt/conda/lib/python3.10/site-packages/bitsandbytes/libbitsandbytes_cuda117.so...
Traceback (most recent call last):
  File "/workspace/qpipe/tests/main_p2p.py", line 300, in <module>
    assert args.method in sols, f"no {args.method} in {sols_path}"
AssertionError: no uniform in /workspace/qpipe/scripts/part_strategy/sols_bloom_176b_Tesla_V100-SXM2-32GB_4_NVIDIA_A100-SXM4-40GB_4.pkl
Traceback (most recent call last):
  File "/workspace/qpipe/tests/main_p2p.py", line 300, in <module>
    assert args.method in sols, f"no {args.method} in {sols_path}"
AssertionError: no uniform in /workspace/qpipe/scripts/part_strategy/sols_bloom_176b_Tesla_V100-SXM2-32GB_4_NVIDIA_A100-SXM4-40GB_4.pkl
Traceback (most recent call last):
  File "/workspace/qpipe/tests/main_p2p.py", line 300, in <module>
    assert args.method in sols, f"no {args.method} in {sols_path}"
AssertionError: no uniform in /workspace/qpipe/scripts/part_strategy/sols_bloom_176b_Tesla_V100-SXM2-32GB_4_NVIDIA_A100-SXM4-40GB_4.pkl
Traceback (most recent call last):
  File "/workspace/qpipe/tests/main_p2p.py", line 300, in <module>
    assert args.method in sols, f"no {args.method} in {sols_path}"
AssertionError: no uniform in /workspace/qpipe/scripts/part_strategy/sols_bloom_176b_Tesla_V100-SXM2-32GB_4_NVIDIA_A100-SXM4-40GB_4.pkl
ERROR:torch.distributed.elastic.multiprocessing.api:failed (exitcode: 1) local_rank: 0 (pid: 247546) of binary: /opt/conda/bin/python
Traceback (most recent call last):
  File "/opt/conda/bin/torchrun", line 33, in <module>
    sys.exit(load_entry_point('torch==2.0.0', 'console_scripts', 'torchrun')())
  File "/opt/conda/lib/python3.10/site-packages/torch/distributed/elastic/multiprocessing/errors/__init__.py", line 346, in wrapper
    return f(*args, **kwargs)
  File "/opt/conda/lib/python3.10/site-packages/torch/distributed/run.py", line 794, in main
    run(args)
  File "/opt/conda/lib/python3.10/site-packages/torch/distributed/run.py", line 785, in run
    elastic_launch(
  File "/opt/conda/lib/python3.10/site-packages/torch/distributed/launcher/api.py", line 134, in __call__
    return launch_agent(self._config, self._entrypoint, list(args))
  File "/opt/conda/lib/python3.10/site-packages/torch/distributed/launcher/api.py", line 250, in launch_agent
    raise ChildFailedError(
torch.distributed.elastic.multiprocessing.errors.ChildFailedError: 
============================================================
main_p2p.py FAILED
------------------------------------------------------------
Failures:
[1]:
  time      : 2023-05-28_10:48:04
  host      : net-g14
  rank      : 5 (local_rank: 1)
  exitcode  : 1 (pid: 247547)
  error_file: <N/A>
  traceback : To enable traceback see: https://pytorch.org/docs/stable/elastic/errors.html
[2]:
  time      : 2023-05-28_10:48:04
  host      : net-g14
  rank      : 6 (local_rank: 2)
  exitcode  : 1 (pid: 247548)
  error_file: <N/A>
  traceback : To enable traceback see: https://pytorch.org/docs/stable/elastic/errors.html
[3]:
  time      : 2023-05-28_10:48:04
  host      : net-g14
  rank      : 7 (local_rank: 3)
  exitcode  : 1 (pid: 247549)
  error_file: <N/A>
  traceback : To enable traceback see: https://pytorch.org/docs/stable/elastic/errors.html
------------------------------------------------------------
Root Cause (first observed failure):
[0]:
  time      : 2023-05-28_10:48:04
  host      : net-g14
  rank      : 4 (local_rank: 0)
  exitcode  : 1 (pid: 247546)
  error_file: <N/A>
  traceback : To enable traceback see: https://pytorch.org/docs/stable/elastic/errors.html
============================================================
