
===================================BUG REPORT===================================
Welcome to bitsandbytes. For bug reports, please run

python -m bitsandbytes

 and submit this information together with your error trace to: https://github.com/TimDettmers/bitsandbytes/issues
================================================================================
bin /opt/conda/lib/python3.10/site-packages/bitsandbytes/libbitsandbytes_cuda117_nocublaslt.so
/opt/conda/lib/python3.10/site-packages/bitsandbytes/cuda_setup/main.py:145: UserWarning: WARNING: The following directories listed in your path were found to be non-existent: {PosixPath('/usr/local/nvidia/lib64'), PosixPath('/usr/local/nvidia/lib')}
  warn(msg)
/opt/conda/lib/python3.10/site-packages/bitsandbytes/cuda_setup/main.py:145: UserWarning: /usr/local/nvidia/lib:/usr/local/nvidia/lib64 did not contain ['libcudart.so', 'libcudart.so.11.0', 'libcudart.so.12.0'] as expected! Searching further paths...
  warn(msg)
/opt/conda/lib/python3.10/site-packages/bitsandbytes/cuda_setup/main.py:145: UserWarning: WARNING: The following directories listed in your path were found to be non-existent: {PosixPath('/tmp/torchelastic_r5wu1lba/none_o4ss3osu/attempt_0/0/error.json')}
  warn(msg)
CUDA_SETUP: WARNING! libcudart.so not found in any environmental path. Searching in backup paths...
/opt/conda/lib/python3.10/site-packages/bitsandbytes/cuda_setup/main.py:145: UserWarning: Found duplicate ['libcudart.so', 'libcudart.so.11.0', 'libcudart.so.12.0'] files: {PosixPath('/usr/local/cuda/lib64/libcudart.so'), PosixPath('/usr/local/cuda/lib64/libcudart.so.11.0')}.. We'll flip a coin and try one of these, in order to fail forward.
Either way, this might cause trouble in the future:
If you get `CUDA error: invalid device function` errors, the above might be the cause and the solution is to make sure only one ['libcudart.so', 'libcudart.so.11.0', 'libcudart.so.12.0'] in the paths that we search based on your env.
  warn(msg)
CUDA SETUP: CUDA runtime path found: /usr/local/cuda/lib64/libcudart.so
CUDA SETUP: Highest compute capability among GPUs detected: 7.0
CUDA SETUP: Detected CUDA version 117
/opt/conda/lib/python3.10/site-packages/bitsandbytes/cuda_setup/main.py:145: UserWarning: WARNING: Compute capability < 7.5 detected! Only slow 8-bit matmul is supported for your GPU!
  warn(msg)
CUDA SETUP: Loading binary /opt/conda/lib/python3.10/site-packages/bitsandbytes/libbitsandbytes_cuda117_nocublaslt.so...
Pipeline Data Loaded, with initial batch size:  1
rank 0 is in stage 0
create layer: 0|create layer: 1|create layer: 2|create layer: 3|create layer: 4|create layer: 5|create layer: 6|create layer: 7|create layer: 8|create layer: 9|create layer: 10|create layer: 11|create layer: 12|create layer: 13|create layer: 14|create layer: 15|create layer: 16|create layer: 17|create layer: 18|create layer: 19|create layer: 20|create layer: 21|create layer: 22|create layer: 23|create layer: 24|create layer: 25|create layer: 26|create layer: 27|create layer: 28|create layer: 29|create layer: 30|create layer: 31|create layer: 32|create layer: 33|create layer: 34|create layer: 35|create layer: 36|create layer: 37|create layer: 38|create layer: 39|Stage 0 module sharded
Traceback (most recent call last):
  File "/workspace/qpipe/tests/main_p2p.py", line 269, in <module>
    run_pipeline_p2p(loaded_llm_cpu, dist_cfg, sharding_strategy=sharding_strategy)
  File "/workspace/qpipe/tests/main_p2p.py", line 164, in run_pipeline_p2p
    module.init_kv_cache(decoder_bss[chunk_id], prompt_length, max_tokens_to_generate, chunk_id)
  File "/opt/conda/lib/python3.10/site-packages/torch/utils/_contextlib.py", line 115, in decorate_context
    return func(*args, **kwargs)
  File "/opt/conda/lib/python3.10/site-packages/qllm/models/OPT/seq_layers.py", line 1483, in init_kv_cache
    return self.model.decoder.init_kv_cache(b, prompt_length, token_to_generate, request_id)
  File "/opt/conda/lib/python3.10/site-packages/torch/utils/_contextlib.py", line 115, in decorate_context
    return func(*args, **kwargs)
  File "/opt/conda/lib/python3.10/site-packages/qllm/models/OPT/seq_layers.py", line 1208, in init_kv_cache
    block.self_attn.init_kv_cache(b, prompt_length, token_to_generate, request_id, torch_dtype=torch_dtype)
  File "/opt/conda/lib/python3.10/site-packages/torch/utils/_contextlib.py", line 115, in decorate_context
    return func(*args, **kwargs)
  File "/opt/conda/lib/python3.10/site-packages/qllm/models/OPT/seq_layers.py", line 472, in init_kv_cache
    self.kv_cache[request_id] = torch.empty(kv_shape_2, dtype=torch_dtype, device=device)
torch.cuda.OutOfMemoryError: CUDA out of memory. Tried to allocate 384.00 MiB (GPU 0; 31.74 GiB total capacity; 13.84 GiB already allocated; 285.62 MiB free; 14.13 GiB reserved in total by PyTorch) If reserved memory is >> allocated memory try setting max_split_size_mb to avoid fragmentation.  See documentation for Memory Management and PYTORCH_CUDA_ALLOC_CONF
ERROR:torch.distributed.elastic.multiprocessing.api:failed (exitcode: 1) local_rank: 0 (pid: 170062) of binary: /opt/conda/bin/python
Traceback (most recent call last):
  File "/opt/conda/bin/torchrun", line 33, in <module>
    sys.exit(load_entry_point('torch==2.0.0', 'console_scripts', 'torchrun')())
  File "/opt/conda/lib/python3.10/site-packages/torch/distributed/elastic/multiprocessing/errors/__init__.py", line 346, in wrapper
    return f(*args, **kwargs)
  File "/opt/conda/lib/python3.10/site-packages/torch/distributed/run.py", line 794, in main
    run(args)
  File "/opt/conda/lib/python3.10/site-packages/torch/distributed/run.py", line 785, in run
    elastic_launch(
  File "/opt/conda/lib/python3.10/site-packages/torch/distributed/launcher/api.py", line 134, in __call__
    return launch_agent(self._config, self._entrypoint, list(args))
  File "/opt/conda/lib/python3.10/site-packages/torch/distributed/launcher/api.py", line 250, in launch_agent
    raise ChildFailedError(
torch.distributed.elastic.multiprocessing.errors.ChildFailedError: 
============================================================
main_p2p.py FAILED
------------------------------------------------------------
Failures:
  <NO_OTHER_FAILURES>
------------------------------------------------------------
Root Cause (first observed failure):
[0]:
  time      : 2023-05-23_07:48:04
  host      : ***REMOVED***
  rank      : 0 (local_rank: 0)
  exitcode  : 1 (pid: 170062)
  error_file: <N/A>
  traceback : To enable traceback see: https://pytorch.org/docs/stable/elastic/errors.html
============================================================
