
===================================BUG REPORT===================================
Welcome to bitsandbytes. For bug reports, please run

python -m bitsandbytes

 and submit this information together with your error trace to: https://github.com/TimDettmers/bitsandbytes/issues
================================================================================
bin /opt/conda/lib/python3.10/site-packages/bitsandbytes/libbitsandbytes_cuda117_nocublaslt.so
/opt/conda/lib/python3.10/site-packages/bitsandbytes/cuda_setup/main.py:145: UserWarning: WARNING: The following directories listed in your path were found to be non-existent: {PosixPath('/usr/local/nvidia/lib'), PosixPath('/usr/local/nvidia/lib64')}
  warn(msg)
/opt/conda/lib/python3.10/site-packages/bitsandbytes/cuda_setup/main.py:145: UserWarning: /usr/local/nvidia/lib:/usr/local/nvidia/lib64 did not contain ['libcudart.so', 'libcudart.so.11.0', 'libcudart.so.12.0'] as expected! Searching further paths...
  warn(msg)
/opt/conda/lib/python3.10/site-packages/bitsandbytes/cuda_setup/main.py:145: UserWarning: WARNING: The following directories listed in your path were found to be non-existent: {PosixPath('/tmp/torchelastic_r323y69o/none_lxjrvmg_/attempt_0/0/error.json')}
  warn(msg)
CUDA_SETUP: WARNING! libcudart.so not found in any environmental path. Searching in backup paths...
/opt/conda/lib/python3.10/site-packages/bitsandbytes/cuda_setup/main.py:145: UserWarning: Found duplicate ['libcudart.so', 'libcudart.so.11.0', 'libcudart.so.12.0'] files: {PosixPath('/usr/local/cuda/lib64/libcudart.so.11.0'), PosixPath('/usr/local/cuda/lib64/libcudart.so')}.. We'll flip a coin and try one of these, in order to fail forward.
Either way, this might cause trouble in the future:
If you get `CUDA error: invalid device function` errors, the above might be the cause and the solution is to make sure only one ['libcudart.so', 'libcudart.so.11.0', 'libcudart.so.12.0'] in the paths that we search based on your env.
  warn(msg)
CUDA SETUP: CUDA runtime path found: /usr/local/cuda/lib64/libcudart.so.11.0
CUDA SETUP: Highest compute capability among GPUs detected: 7.0
CUDA SETUP: Detected CUDA version 117
/opt/conda/lib/python3.10/site-packages/bitsandbytes/cuda_setup/main.py:145: UserWarning: WARNING: Compute capability < 7.5 detected! Only slow 8-bit matmul is supported for your GPU!
  warn(msg)
CUDA SETUP: Loading binary /opt/conda/lib/python3.10/site-packages/bitsandbytes/libbitsandbytes_cuda117_nocublaslt.so...
prompt_length 128
rank 3 is in stage 3
create layer: 36|create layer: 37|create layer: 38|create layer: 39|create layer: 40|create layer: 41|create layer: 42|create layer: 43|create layer: 44|create layer: 45|create layer: 46|create layer: 47|Stage 3 module sharded
Stage 3 kv initialized
rank_src: 2, rank_dst: 0, rank: 3, results_cb: None
2023-06-05 14:46:20,862 - INFO - handle_cmd: stop
Traceback (most recent call last):
  File "/workspace/qpipe/tests/main_p2p.py", line 330, in <module>
    simple_queue_thread.join()
AttributeError: 'NoneType' object has no attribute 'join'
ERROR:torch.distributed.elastic.multiprocessing.api:failed (exitcode: 1) local_rank: 0 (pid: 36627) of binary: /opt/conda/bin/python
ERROR:torch.distributed.elastic.agent.server.api:Error waiting on exit barrier. Elapsed: 315.598925113678 seconds
Traceback (most recent call last):
  File "/opt/conda/lib/python3.10/site-packages/torch/distributed/elastic/agent/server/api.py", line 920, in _exit_barrier
    store_util.barrier(
  File "/opt/conda/lib/python3.10/site-packages/torch/distributed/elastic/utils/store.py", line 78, in barrier
    synchronize(store, data, rank, world_size, key_prefix, barrier_timeout)
  File "/opt/conda/lib/python3.10/site-packages/torch/distributed/elastic/utils/store.py", line 64, in synchronize
    agent_data = get_all(store, rank, key_prefix, world_size)
  File "/opt/conda/lib/python3.10/site-packages/torch/distributed/elastic/utils/store.py", line 34, in get_all
    data = store.get(f"{prefix}{idx}")
RuntimeError: Socket Timeout
Traceback (most recent call last):
  File "/opt/conda/bin/torchrun", line 33, in <module>
    sys.exit(load_entry_point('torch==2.0.0', 'console_scripts', 'torchrun')())
  File "/opt/conda/lib/python3.10/site-packages/torch/distributed/elastic/multiprocessing/errors/__init__.py", line 346, in wrapper
    return f(*args, **kwargs)
  File "/opt/conda/lib/python3.10/site-packages/torch/distributed/run.py", line 794, in main
    run(args)
  File "/opt/conda/lib/python3.10/site-packages/torch/distributed/run.py", line 785, in run
    elastic_launch(
  File "/opt/conda/lib/python3.10/site-packages/torch/distributed/launcher/api.py", line 134, in __call__
    return launch_agent(self._config, self._entrypoint, list(args))
  File "/opt/conda/lib/python3.10/site-packages/torch/distributed/launcher/api.py", line 250, in launch_agent
    raise ChildFailedError(
torch.distributed.elastic.multiprocessing.errors.ChildFailedError: 
============================================================
main_p2p.py FAILED
------------------------------------------------------------
Failures:
  <NO_OTHER_FAILURES>
------------------------------------------------------------
Root Cause (first observed failure):
[0]:
  time      : 2023-06-05_14:46:23
  host      : ***REMOVED***
  rank      : 3 (local_rank: 0)
  exitcode  : 1 (pid: 36627)
  error_file: <N/A>
  traceback : To enable traceback see: https://pytorch.org/docs/stable/elastic/errors.html
============================================================
